Traceback (most recent call last):
  File "/usr/bin/jack_control", line 399, in <module>
    main()
  File "/usr/bin/jack_control", line 158, in main
    bus = dbus.SessionBus()
  File "/usr/lib/python2.7/dist-packages/dbus/_dbus.py", line 211, in __new__
    mainloop=mainloop)
  File "/usr/lib/python2.7/dist-packages/dbus/_dbus.py", line 100, in __new__
    bus = BusConnection.__new__(subclass, bus_type, mainloop=mainloop)
  File "/usr/lib/python2.7/dist-packages/dbus/bus.py", line 122, in __new__
    bus = cls._new_for_bus(address_or_type, mainloop=mainloop)
dbus.exceptions.DBusException: org.freedesktop.DBus.Error.NotSupported: Unable to autolaunch a dbus-daemon without a $DISPLAY for X11
Traceback (most recent call last):
  File "/usr/lib/python3/dist-packages/urllib3/connectionpool.py", line 516, in urlopen
    body=body, headers=headers)
  File "/usr/lib/python3/dist-packages/urllib3/connectionpool.py", line 304, in _make_request
    self._validate_conn(conn)
  File "/usr/lib/python3/dist-packages/urllib3/connectionpool.py", line 724, in _validate_conn
    conn.connect()
  File "/usr/lib/python3/dist-packages/urllib3/connection.py", line 203, in connect
    conn = self._new_conn()
  File "/usr/lib/python3/dist-packages/urllib3/connection.py", line 133, in _new_conn
    (self.host, self.port), self.timeout, **extra_kw)
  File "/usr/lib/python3/dist-packages/urllib3/util/connection.py", line 64, in create_connection
    for res in socket.getaddrinfo(host, port, 0, socket.SOCK_STREAM):
  File "/usr/lib/python3.4/socket.py", line 530, in getaddrinfo
    for res in _socket.getaddrinfo(host, port, family, type, proto, flags):
socket.gaierror: [Errno -2] Name or service not known

During handling of the above exception, another exception occurred:

Traceback (most recent call last):
  File "/usr/lib/python3/dist-packages/requests/adapters.py", line 362, in send
    timeout=timeout
  File "/usr/lib/python3/dist-packages/urllib3/connectionpool.py", line 559, in urlopen
    _pool=self, _stacktrace=stacktrace)
  File "/usr/lib/python3/dist-packages/urllib3/util/retry.py", line 245, in increment
    raise six.reraise(type(error), error, _stacktrace)
  File "/usr/lib/python3/dist-packages/six.py", line 624, in reraise
    raise value.with_traceback(tb)
  File "/usr/lib/python3/dist-packages/urllib3/connectionpool.py", line 516, in urlopen
    body=body, headers=headers)
  File "/usr/lib/python3/dist-packages/urllib3/connectionpool.py", line 304, in _make_request
    self._validate_conn(conn)
  File "/usr/lib/python3/dist-packages/urllib3/connectionpool.py", line 724, in _validate_conn
    conn.connect()
  File "/usr/lib/python3/dist-packages/urllib3/connection.py", line 203, in connect
    conn = self._new_conn()
  File "/usr/lib/python3/dist-packages/urllib3/connection.py", line 133, in _new_conn
    (self.host, self.port), self.timeout, **extra_kw)
  File "/usr/lib/python3/dist-packages/urllib3/util/connection.py", line 64, in create_connection
    for res in socket.getaddrinfo(host, port, 0, socket.SOCK_STREAM):
  File "/usr/lib/python3.4/socket.py", line 530, in getaddrinfo
    for res in _socket.getaddrinfo(host, port, family, type, proto, flags):
urllib3.exceptions.ProtocolError: ('Connection aborted.', gaierror(-2, 'Name or service not known'))

During handling of the above exception, another exception occurred:

Traceback (most recent call last):
  File "cap_and_send.py", line 26, in <module>
    playback("Hello, I am Kobo, your home assistant.  The date is %s.  Say something when you are ready to begin." % t[1])
  File "cap_and_send.py", line 19, in playback
    tts.save(kobo_voice)
  File "/usr/local/lib/python3.4/dist-packages/gtts/tts.py", line 94, in save
    self.write_to_fp(f)
  File "/usr/local/lib/python3.4/dist-packages/gtts/tts.py", line 107, in write_to_fp
    'tk' : self.token.calculate_token(part)}
  File "/usr/local/lib/python3.4/dist-packages/gtts_token/gtts_token.py", line 28, in calculate_token
    seed = self._get_token_key()
  File "/usr/local/lib/python3.4/dist-packages/gtts_token/gtts_token.py", line 58, in _get_token_key
    response = requests.get("https://translate.google.com/")
  File "/usr/lib/python3/dist-packages/requests/api.py", line 60, in get
    return request('get', url, **kwargs)
  File "/usr/lib/python3/dist-packages/requests/api.py", line 49, in request
    return session.request(method=method, url=url, **kwargs)
  File "/usr/lib/python3/dist-packages/requests/sessions.py", line 457, in request
    resp = self.send(prep, **send_kwargs)
  File "/usr/lib/python3/dist-packages/requests/sessions.py", line 569, in send
    r = adapter.send(request, **kwargs)
  File "/usr/lib/python3/dist-packages/requests/adapters.py", line 407, in send
    raise ConnectionError(err, request=request)
requests.exceptions.ConnectionError: ('Connection aborted.', gaierror(-2, 'Name or service not known'))
